Workbook

Sheet Récap
A1: Atelier by – Halle · tableau récap
A2: Mars → septembre 2026 (7 mois pleins), lu le 13 octobre 2026. Hors TVA. Food cost retenu : 45 % (case B31, appliquée à tous les mois). En vert : liens vers « Mois par mois » ; en bleu : chiffres lus ; fond jaune : hypothèses à modifier ; en noir : calculs.
A4: Ventes et clients | B4: Actuel (moy. mars → sept.) | C4: Octobre 1 → 12 | D4: Objectif | E4: Écart actuel → objectif | F4: Note
A5: CA par mois | B5: ='Mois par mois'!C13 -> 51603.366 | D5: =B12 -> 61000 | E5: =D5-B5 -> 9396.6343
A6: CA par jour | B6: ='Mois par mois'!H13 -> 1695.8853 | C6: ='Mois par mois'!H16 -> 1950.1458 | D6: =B12/B13 -> 2005.4795 | E6: =D6-B6 -> 309.59419
A7: Clients par mois | B7: ='Mois par mois'!F13 -> 4235.5714 | D7: =IF(B9>0,B12/B9,0) -> 5006.8412 | E7: =D7-B7 -> 771.26976 | F7: objectif : au panier actuel
A8: Clients par jour | B8: ='Mois par mois'!I13 -> 139.19718 | C8: ='Mois par mois'!I16 -> 152.91667 | D8: =D7/B13 -> 164.60848 | E8: =D8-B8 -> 25.411294 | F8: objectif : au panier actuel
A9: Panier moyen | B9: ='Mois par mois'!G13 -> 12.18333 | C9: ='Mois par mois'!G16 -> 12.752997 | D9: =IF(B7>0,B12/B7,0) -> 14.401835 | E9: =D9-B9 -> 2.2185045 | F9: objectif : avec le nombre de clients actuel
A10: Atteinte du budget | B10: ='Mois par mois'!E12 -> 0.83616565 | C10: ='Mois par mois'!E16 -> 0.98185796 | F10: octobre : face à l’objectif à date (budget réparti par jour de semaine)
A12: Objectif de CA mensuel (budget validé, août → décembre) | B12: 61000 | F12: hypothèse : remplacer pour tester un autre objectif
A13: Jours par mois (ouvert 7 jours sur 7) | B13: =365/12 -> 30.416667
A14: Panier moyen des 3 autres magasins (repère) | B14: 14.26
A15: CA sur 12 mois au rythme actuel | B15: =B5*12 -> 619240.39
A16: CA sur 12 mois à l’objectif | B16: =B12*12 -> 732000
A17: Potentiel année 1 de l’étude de marché (CA annuel) | B17: 840000
A20: Les coûts du magasin (par mois) | B20: Moy. mars → sept. | C20: % du CA | D20: Moy. juil. → sept. | E20: % du CA | F20: Repère
A21: Matière (food cost) | B21: ='Mois par mois'!K13 -> 23221.515 | C21: =IF('Mois par mois'!C13>0,B21/'Mois par mois'!C13,0) -> 0.45 | D21: ='Mois par mois'!K14 -> 22415.588 | E21: =IF('Mois par mois'!C14>0,D21/'Mois par mois'!C14,0) -> 0.45 | F21: food cost retenu 45 % (case B31) ; mesuré 37,4 % au panel ; seuil réseau 32 %
A22: Main-d’œuvre | B22: ='Mois par mois'!L13 -> 11573.469 | C22: =IF('Mois par mois'!C13>0,B22/'Mois par mois'!C13,0) -> 0.22427741 | D22: ='Mois par mois'!L14 -> 11609.524 | E22: =IF('Mois par mois'!C14>0,D22/'Mois par mois'!C14,0) -> 0.23306486 | F22: 2 650 € par semaine (case C28) ; encodée au panel : 8 100 € par mois ; seuil réseau 33 %
A23: Frais généraux encodés | B23: ='Mois par mois'!P13 -> 12612.671 | C23: =IF('Mois par mois'!C13>0,B23/'Mois par mois'!C13,0) -> 0.24441567 | D23: ='Mois par mois'!P14 -> 13042.687 | E23: =IF('Mois par mois'!C14>0,D23/'Mois par mois'!C14,0) -> 0.26183605 | F23: montant mensuel saisi au panel, sans détail (voir « Modèle de charges »)
A24: Total des coûts | B24: =SUM(B21:B23) -> 47407.655 | C24: =IF('Mois par mois'!C13>0,B24/'Mois par mois'!C13,0) -> 0.91869309 | D24: =SUM(D21:D23) -> 47067.798 | E24: =IF('Mois par mois'!C14>0,D24/'Mois par mois'!C14,0) -> 0.94490091
A25: Résultat opérationnel | B25: ='Mois par mois'!C13-B24 -> 4195.7103 | C25: =IF('Mois par mois'!C13>0,B25/'Mois par mois'!C13,0) -> 0.081306912 | D25: ='Mois par mois'!C14-D24 -> 2744.6187 | E25: =IF('Mois par mois'!C14>0,D25/'Mois par mois'!C14,0) -> 0.055099087 | F25: avant charges financières et impôts
A27: Le point mort (structure de coûts juillet → septembre) | B27: Valeur | C27: € par semaine | F27: Comment
A28: Main-d’œuvre par mois (la semaine en C, × 365/12 ÷ 7) | B28: =C28*B13/7 -> 11514.881 | C28: 2650 | F28: hypothèse : 2 650 € par semaine (case C28) ; encodée au panel : 8 585 € par mois en juillet → septembre
A29: Frais généraux par mois | B29: ='Mois par mois'!P14 -> 13042.687 | F29: octobre : 486,38 € par jour au panel, soit ≈ 15 080 € par mois
A30: Autres charges fixes à ajouter (rémunération du gérant…) | B30: 0 | F30: absentes du panel : à renseigner avec le franchisé
A31: Food cost (hypothèse, s’applique à tous les mois) | B31: 0.45 | F31: hypothèse demandée ; mesuré 36,5 % par le panel (juillet → septembre), 43,9 % ticket par ticket (août-septembre)
A32: Charges fixes par mois | B32: =SUM(B28:B30) -> 24557.568
A33: Taux de marge brute (1 − food cost) | B33: =1-B31 -> 0.55
A34: Point mort, CA par mois | B34: =IF(B33>0,B32/B33,0) -> 44650.123 | F34: charges fixes ÷ taux de marge brute
A35: Point mort, CA par jour | B35: =B34/B13 -> 1467.9492
A36: Point mort, clients par jour au panier actuel | B36: =IF(B9>0,B35/B9,0) -> 120.48834
A37: Marge de sécurité (baisse de CA possible avant le point mort) | B37: =IF(B5>0,1-B34/B5,0) -> 0.13474398 | F37: face au CA moyen mars → septembre
A38: Résultat au CA actuel (par mois) | B38: =B5*B33-B32 -> 3824.2835 | F38: avec ces hypothèses
A39: Résultat à l’objectif (par mois) | B39: =B12*B33-B32 -> 8992.4324
A40: Point mort en plus pour 1 000 € de charges fixes | B40: =IF(B33>0,1000/B33,0) -> 1818.1818
A41: Résultat en plus pour 1 000 € de CA | B41: =1000*B33 -> 550
A43: Le point mort selon les hypothèses | B43: Charges fixes | C43: Food cost | D43: Point mort / mois | E43: Point mort / jour | F43: Marge de sécurité
A44: Food cost retenu, charges juillet → septembre | B44: =$B$28+'Mois par mois'!P14 -> 24557.568 | C44: ='Mois par mois'!J14 -> 0.45 | D44: =IF(C44<1,B44/(1-C44),0) -> 44650.123 | E44: =D44/$B$13 -> 1467.9492 | F44: =IF($B$5>0,1-D44/$B$5,0) -> 0.13474398
A45: Le même, avec les frais généraux d’octobre (par jour × 31) | B45: =$B$28+'Mois par mois'!P16*31 -> 26592.661 | C45: ='Mois par mois'!J14 -> 0.45 | D45: =IF(C45<1,B45/(1-C45),0) -> 48350.293 | E45: =D45/$B$13 -> 1589.5987 | F45: =IF($B$5>0,1-D45/$B$5,0) -> 0.06303994
A46: Food cost recomposé ticket par ticket (août-septembre) | B46: =B44 -> 24557.568 | C46: 0.4386 | D46: =IF(C46<1,B46/(1-C46),0) -> 43743.441 | E46: =D46/$B$13 -> 1438.1405 | F46: =IF($B$5>0,1-D46/$B$5,0) -> 0.15231419
...

Sheet Mois par mois
A1: Atelier by – Halle · les mois pleins, mars → septembre 2026
A2: Lu le 13 octobre 2026 sur le panel (P&L quotidien agrégé par mois : CA, main-d’œuvre, frais généraux) et le cockpit (tickets, food cost mesuré par le panel, budget, heures planifiées). En bleu : les chiffres lus ; en noir : les calculs. Hors TVA. Juin et juillet : travaux du viaduc de Halle (effet estimé − 20 %).
A4: Mois | B4: Jours de vente | C4: CA (€) | D4: Budget CA (€) | E4: Atteinte | F4: Clients (tickets) | G4: Panier moyen (€) | H4: CA par jour (€) | I4: Clients par jour | J4: Food cost retenu (% CA) | K4: Matière (€) | L4: Main-d’œuvre retenue (€) | M4: Main-d’œuvre (% CA) | N4: Heures planifiées | O4: Coût horaire retenu (€/h) | P4: Frais généraux encodés (€) | Q4: Frais généraux (% CA) | R4: Résultat opérationnel encodé (€) | S4: Résultat (% CA) | T4: Food cost mesuré par le panel (% CA) | U4: Main-d’œuvre encodée au panel (€)
A5: Mars | B5: 31 | C5: 48767.34 | D5: 62000 | E5: =IF(D5>0,C5/D5,0) -> 0.78657 | F5: 4341 | G5: =IF(F5>0,C5/F5,0) -> 11.234126 | H5: =IF(B5>0,C5/B5,0) -> 1573.14 | I5: =IF(B5>0,F5/B5,0) -> 140.03226 | J5: =Récap!$B$31 -> 0.45 | K5: =C5*J5 -> 21945.303 | L5: =Récap!$C$28*31/7 -> 11735.714 | M5: =IF(C5>0,L5/C5,0) -> 0.240647 | N5: 801.5 | O5: =IF(N5>0,L5/N5,0) -> 14.642189 | P5: 9359.52 | Q5: =IF(C5>0,P5/C5,0) -> 0.19192189 | R5: =C5-K5-L5-P5 -> 5726.8027 | S5: =IF(C5>0,R5/C5,0) -> 0.11743111 | T5: 0.398 | U5: 6334
A6: Avril | B6: 30 | C6: 55831.57 | D6: 62000 | E6: =IF(D6>0,C6/D6,0) -> 0.90050919 | F6: 4486 | G6: =IF(F6>0,C6/F6,0) -> 12.445736 | H6: =IF(B6>0,C6/B6,0) -> 1861.0523 | I6: =IF(B6>0,F6/B6,0) -> 149.53333 | J6: =Récap!$B$31 -> 0.45 | K6: =C6*J6 -> 25124.207 | L6: =Récap!$C$28*30/7 -> 11357.143 | M6: =IF(C6>0,L6/C6,0) -> 0.20341794 | N6: 758 | O6: =IF(N6>0,L6/N6,0) -> 14.983038 | P6: 9608.7 | Q6: =IF(C6>0,P6/C6,0) -> 0.17210155 | R6: =C6-K6-L6-P6 -> 9741.5206 | S6: =IF(C6>0,R6/C6,0) -> 0.17448051 | T6: 0.391 | U6: 5814.5
A7: Mai | B7: 31 | C7: 60239.57 | D7: 62000 | E7: =IF(D7>0,C7/D7,0) -> 0.97160597 | F7: 4756 | G7: =IF(F7>0,C7/F7,0) -> 12.666016 | H7: =IF(B7>0,C7/B7,0) -> 1943.2119 | I7: =IF(B7>0,F7/B7,0) -> 153.41935 | J7: =Récap!$B$31 -> 0.45 | K7: =C7*J7 -> 27107.806 | L7: =Récap!$C$28*31/7 -> 11735.714 | M7: =IF(C7>0,L7/C7,0) -> 0.19481736 | N7: 628 | O7: =IF(N7>0,L7/N7,0) -> 18.687443 | P7: 19533.72 | Q7: =IF(C7>0,P7/C7,0) -> 0.32426725 | R7: =C7-K7-L7-P7 -> 1862.3292 | S7: =IF(C7>0,R7/C7,0) -> 0.03091538 | T7: 0.372 | U7: 10080.5
A8: Juin (travaux viaduc) | B8: 30 | C8: 46947.83 | D8: 62000 | E8: =IF(D8>0,C8/D8,0) -> 0.75722306 | F8: 3811 | G8: =IF(F8>0,C8/F8,0) -> 12.319032 | H8: =IF(B8>0,C8/B8,0) -> 1564.9277 | I8: =IF(B8>0,F8/B8,0) -> 127.03333 | J8: =Récap!$B$31 -> 0.45 | K8: =C8*J8 -> 21126.523 | L8: =Récap!$C$28*30/7 -> 11357.143 | M8: =IF(C8>0,L8/C8,0) -> 0.24190986 | N8: 617.5 | O8: =IF(N8>0,L8/N8,0) -> 18.392134 | P8: 10658.7 | Q8: =IF(C8>0,P8/C8,0) -> 0.22703286 | R8: =C8-K8-L8-P8 -> 3805.4636 | S8: =IF(C8>0,R8/C8,0) -> 0.081057285 | T8: 0.363 | U8: 8714
A9: Juillet (travaux viaduc) | B9: 30 | C9: 46236.55 | D9: 62000 | E9: =IF(D9>0,C9/D9,0) -> 0.74575081 | F9: 3776 | G9: =IF(F9>0,C9/F9,0) -> 12.244849 | H9: =IF(B9>0,C9/B9,0) -> 1541.2183 | I9: =IF(B9>0,F9/B9,0) -> 125.86667 | J9: =Récap!$B$31 -> 0.45 | K9: =C9*J9 -> 20806.447 | L9: =Récap!$C$28*31/7 -> 11735.714 | M9: =IF(C9>0,L9/C9,0) -> 0.25381899 | N9: 675.5 | O9: =IF(N9>0,L9/N9,0) -> 17.373374 | P9: 13042.63 | Q9: =IF(C9>0,P9/C9,0) -> 0.28208484 | R9: =C9-K9-L9-P9 -> 651.75821 | S9: =IF(C9>0,R9/C9,0) -> 0.014096169 | T9: 0.368 | U9: 8110.75
A10: Août | B10: 31 | C10: 52350.95 | D10: 61000 | E10: =IF(D10>0,C10/D10,0) -> 0.8582123 | F10: 4323 | G10: =IF(F10>0,C10/F10,0) -> 12.109866 | H10: =IF(B10>0,C10/B10,0) -> 1688.7403 | I10: =IF(B10>0,F10/B10,0) -> 139.45161 | J10: =Récap!$B$31 -> 0.45 | K10: =C10*J10 -> 23557.928 | L10: =Récap!$C$28*31/7 -> 11735.714 | M10: =IF(C10>0,L10/C10,0) -> 0.22417386 | N10: 792 | O10: =IF(N10>0,L10/N10,0) -> 14.817821 | P10: 13042.63 | Q10: =IF(C10>0,P10/C10,0) -> 0.24913836 | R10: =C10-K10-L10-P10 -> 4014.6782 | S10: =IF(C10>0,R10/C10,0) -> 0.076687781 | T10: 0.364 | U10: 8167.75
A11: Septembre | B11: 30 | C11: 50849.75 | D11: 61000 | E11: =IF(D11>0,C11/D11,0) -> 0.83360246 | F11: 4156 | G11: =IF(F11>0,C11/F11,0) -> 12.235262 | H11: =IF(B11>0,C11/B11,0) -> 1694.9917 | I11: =IF(B11>0,F11/B11,0) -> 138.53333 | J11: =Récap!$B$31 -> 0.45 | K11: =C11*J11 -> 22882.388 | L11: =Récap!$C$28*30/7 -> 11357.143 | M11: =IF(C11>0,L11/C11,0) -> 0.22334707 | N11: 782 | O11: =IF(N11>0,L11/N11,0) -> 14.523201 | P11: 13042.8 | Q11: =IF(C11>0,P11/C11,0) -> 0.25649684 | R11: =C11-K11-L11-P11 -> 3567.4196 | S11: =IF(C11>0,R11/C11,0) -> 0.07015609 | T11: 0.362 | U11: 9477.5
A12: Total mars → septembre | B12: =SUM(B5:B11) -> 213 | C12: =SUM(C5:C11) -> 361223.56 | D12: =SUM(D5:D11) -> 432000 | E12: =IF(D12>0,C12/D12,0) -> 0.83616565 | F12: =SUM(F5:F11) -> 29649 | G12: =IF(F12>0,C12/F12,0) -> 12.18333 | H12: =IF(B12>0,C12/B12,0) -> 1695.8853 | I12: =IF(B12>0,F12/B12,0) -> 139.19718 | J12: =IF(C12>0,K12/C12,0) -> 0.45 | K12: =SUM(K5:K11) -> 162550.6 | L12: =SUM(L5:L11) -> 81014.286 | M12: =IF(C12>0,L12/C12,0) -> 0.22427741 | N12: =SUM(N5:N11) -> 5054.5 | O12: =IF(N12>0,L12/N12,0) -> 16.02815 | P12: =SUM(P5:P11) -> 88288.7 | Q12: =IF(C12>0,P12/C12,0) -> 0.24441567 | R12: =SUM(R5:R11) -> 29369.972 | S12: =IF(C12>0,R12/C12,0) -> 0.081306912 | T12: =IF(SUM(C5:C11)>0,SUMPRODUCT(C5:C11,T5:T11)/SUM(C5:C11),0) -> 0.374198 | U12: =SUM(U5:U11) -> 56699
A13: Moyenne par mois, mars → septembre | B13: =AVERAGE(B5:B11) -> 30.428571 | C13: =AVERAGE(C5:C11) -> 51603.366 | D13: =AVERAGE(D5:D11) -> 61714.286 | E13: =IF(D13>0,C13/D13,0) -> 0.83616565 | F13: =AVERAGE(F5:F11) -> 4235.5714 | G13: =IF(F13>0,C13/F13,0) -> 12.18333 | H13: =IF(B13>0,C13/B13,0) -> 1695.8853 | I13: =IF(B13>0,F13/B13,0) -> 139.19718 | J13: =IF(C13>0,K13/C13,0) -> 0.45 | K13: =AVERAGE(K5:K11) -> 23221.515 | L13: =AVERAGE(L5:L11) -> 11573.469 | M13: =IF(C13>0,L13/C13,0) -> 0.22427741 | N13: =AVERAGE(N5:N11) -> 722.07143 | O13: =IF(N13>0,L13/N13,0) -> 16.02815 | P13: =AVERAGE(P5:P11) -> 12612.671 | Q13: =IF(C13>0,P13/C13,0) -> 0.24441567 | R13: =AVERAGE(R5:R11) -> 4195.7103 | S13: =IF(C13>0,R13/C13,0) -> 0.081306912 | T13: =IF(SUM(C5:C11)>0,SUMPRODUCT(C5:C11,T5:T11)/SUM(C5:C11),0) -> 0.374198 | U13: =AVERAGE(U5:U11) -> 8099.8571
A14: Moyenne par mois, juillet → septembre (structure actuelle) | B14: =AVERAGE(B9:B11) -> 30.333333 | C14: =AVERAGE(C9:C11) -> 49812.417 | D14: =AVERAGE(D9:D11) -> 61333.333 | E14: =IF(D14>0,C14/D14,0) -> 0.81215897 | F14: =AVERAGE(F9:F11) -> 4085 | G14: =IF(F14>0,C14/F14,0) -> 12.193982 | H14: =IF(B14>0,C14/B14,0) -> 1642.1676 | I14: =IF(B14>0,F14/B14,0) -> 134.67033 | J14: =IF(C14>0,K14/C14,0) -> 0.45 | K14: =AVERAGE(K9:K11) -> 22415.588 | L14: =AVERAGE(L9:L11) -> 11609.524 | M14: =IF(C14>0,L14/C14,0) -> 0.23306486 | N14: =AVERAGE(N9:N11) -> 749.83333 | O14: =IF(N14>0,L14/N14,0) -> 15.482806 | P14: =AVERAGE(P9:P11) -> 13042.687 | Q14: =IF(C14>0,P14/C14,0) -> 0.26183605 | R14: =AVERAGE(R9:R11) -> 2744.6187 | S14: =IF(C14>0,R14/C14,0) -> 0.055099087 | T14: =IF(SUM(C9:C11)>0,SUMPRODUCT(C9:C11,T9:T11)/SUM(C9:C11),0) -> 0.36455707 | U14: =AVERAGE(U9:U11) -> 8585.3333
A16: Octobre, 1 → 12 (en cours) | B16: 12 | C16: 23401.75 | D16: 23834.15 | E16: =IF(D16>0,C16/D16,0) -> 0.98185796 | F16: 1835 | G16: =IF(F16>0,C16/F16,0) -> 12.752997 | H16: =IF(B16>0,C16/B16,0) -> 1950.1458 | I16: =IF(B16>0,F16/B16,0) -> 152.91667 | P16: 486.38 | Q16: ← € par jour

Sheet Modèle de charges
A1: Le modèle de charges du budget franchisé (Halle, exercice 2026)
A2: Les hypothèses du franchiseur, en part du CA — pas des montants constatés : le loyer réel vient du bail, l’énergie des factures. Le € par mois se calcule sur le CA moyen mars → septembre.
A3: CA moyen par mois (mars → septembre) | C3: ='Mois par mois'!C13 -> 51603.366
A5: Catégorie | B5: Poste | C5: Budget (% du CA) | D5: Théorique (% du CA) | E5: € par mois au rythme actuel (budget) | F5: Gestion
A6: Matière première & Emballage | B6: Matière première | C6: 0 | D6: 0.36 | E6: =C6*$C$3 -> 0
A7: Matière première & Emballage | B7: Emballage | C7: 0 | D7: 0.02 | E7: =C7*$C$3 -> 0
A8: Occupation | B8: Loyer + charges locatives | C8: 0.07 | D8: 0.07 | E8: =C8*$C$3 -> 3612.2356 | F8: Fixe
A9: Occupation | B9: Énergie (eau, gaz, électricité) | C9: 0.05 | D9: 0.05 | E9: =C9*$C$3 -> 2580.1683 | F9: Groupement d’achat, appel d’offres
A10: Occupation | B10: Maintenance & nettoyage | C10: 0.01 | D10: 0.005 | E10: =C10*$C$3 -> 516.03366 | F10: Préventif et régulier
A11: Occupation | B11: Assurances, licences, etc. | C11: 0.01 | D11: 0.01 | E11: =C11*$C$3 -> 516.03366 | F11: Suivi des échéances
A12: Redevances de marque | B12: Royalties franchise | C12: 0.02 | D12: 0.02 | E12: =C12*$C$3 -> 1032.0673 | F12: Fixe
A13: Redevances de marque | B13: Redevance assistance | C13: 0.015 | D13: 0.015 | E13: =C13*$C$3 -> 774.05049 | F13: Fixe
A14: Redevances de marque | B14: Marketing national / local | C14: 0.015 | D14: 0.015 | E14: =C14*$C$3 -> 774.05049 | F14: Fixe
A15: Investissement | B15: Amortissements / leasing matériel | C15: 0.05 | D15: 0.07 | E15: =C15*$C$3 -> 2580.1683 | F15: Fixe
A16: Frais généraux | B16: Autres (comptabilité, banque, divers) | C16: 0.015 | D16: 0.015 | E16: =C16*$C$3 -> 774.05049 | F16: Optimisation des prestataires
B17: Total des postes budgétés | C17: =SUM(C6:C16) -> 0.255 | E17: =SUM(E6:E16) -> 13158.858
A19: Frais généraux encodés au panel, par mois (juillet → septembre) | E19: ='Mois par mois'!P14 -> 13042.687
A20: La matière (36 %) et l’emballage (2 %) ne sont qu’en théorique dans ce modèle : le food cost mesuré en tient lieu.

Sheet Compte d’exploitation
A1: Le compte d’exploitation comptable, mars → septembre 2026 (à valider)
A2: Situation au 30/09/2026 de la fiduciaire (Pardoen), ramenée au mois sur les 7 mois d’exploitation (ouverture en mars) ; loyer, charges locatives, assurance et honoraires à leur coût mensuel. En bleu : montants de l’analyse ; fond jaune : paramètres et résultats visés ; en noir : calculs.
A4: Paramètres
A5: Rémunération de Nathan, € par semaine | B5: 500 | C5: absente des comptes
A6: Remboursements crédits et leasing, € par mois | B6: 2900 | C6: ≈ 211 k€ sur 10 ans et 38 k€ sur 5 ans
A7: Semaines par mois | B7: =52/12 -> 4.3333333
A8: Jours par mois | B8: =365/12 -> 30.416667 | C8: ouvert 7 jours sur 7
A9: Mois d’exploitation (ouverture en mars) | B9: 7 | C9: pour ramener au mois les totaux de la période
A10: Hausse de prix moyenne (plan B1) | B10: 0.05 | C10: baguette et tradition inchangées ; volumes supposés inchangés
A11: Commandes sur ventes réelles (B2), % des achats | B11: 0.08
A12: Hausse de CA du scénario | B12: 0.15 | C12: les + 15 % visés
A13: Matière du scénario (% du CA) | B13: 0.4 | C13: la cible du plan
A18: Résultat visé après Nathan et la banque (€ par mois) | D18: 0 | E18: 5000 | F18: 10000
A19: Poste (€ par mois) | B19: Analyse | C19: % CA | D19: CA pour le résultat visé | E19: CA pour le résultat visé | F19: CA pour le résultat visé | G19: Plan achats (B1 + B2) | H19: % CA | I19: + 15 % de CA, matière 40 % | J19: % CA
A20: Chiffre d’affaires | B20: 49899.43 | C20: =IF(B$20<>0,B20/B$20,0) -> 1 | D20: =(SUM($B$24:$B$35)+$B$5*$B$7+$B$6+D$18)/(1-($B$21+$B$22)/$B$20) -> 54482.91 | E20: =(SUM($B$24:$B$35)+$B$5*$B$7+$B$6+E$18)/(1-($B$21+$B$22)/$B$20) -> 64465.763 | F20: =(SUM($B$24:$B$35)+$B$5*$B$7+$B$6+F$18)/(1-($B$21+$B$22)/$B$20) -> 74448.616 | G20: =B20*(1+$B$10) -> 52394.401 | H20: =IF(G$20<>0,G20/G$20,0) -> 1 | I20: =B20*(1+$B$12) -> 57384.344 | J20: =IF(I$20<>0,I20/I$20,0) -> 1
A21: Achats matière (marchandises + fournitures + boissons) | B21: 24123.43 | C21: =IF(B$20<>0,B21/B$20,0) -> 0.48344099 | D21: =D20*$B$21/$B$20 -> 26339.272 | E21: =E20*$B$21/$B$20 -> 31165.393 | F21: =F20*$B$21/$B$20 -> 35991.513 | G21: =B21*(1-$B$11) -> 22193.556 | H21: =IF(G$20<>0,G21/G$20,0) -> 0.42358639 | I21: =I20*$B$13 -> 22953.738 | J21: =IF(I$20<>0,I21/I$20,0) -> 0.4
A22: Emballages | B22: 783.43 | C22: =IF(B$20<>0,B22/B$20,0) -> 0.015700179 | D22: =D20*$B$22/$B$20 -> 855.39147 | E22: =E20*$B$22/$B$20 -> 1012.124 | F22: =F20*$B$22/$B$20 -> 1168.8566 | G22: =B22 -> 783.43 | H22: =IF(G$20<>0,G22/G$20,0) -> 0.014952552 | I22: =IF(B20>0,B22/B20*I20,0) -> 900.9445 | J22: =IF(I$20<>0,I22/I$20,0) -> 0.015700179
A23: Marge brute | B23: =B20-B21-B22 -> 24992.57 | C23: =IF(B$20<>0,B23/B$20,0) -> 0.50085883 | D23: =D20-D21-D22 -> 27288.247 | E23: =E20-E21-E22 -> 32288.247 | F23: =F20-F21-F22 -> 37288.247 | G23: =G20-G21-G22 -> 29417.416 | H23: =IF(G$20<>0,G23/G$20,0) -> 0.56146105 | I23: =I20-I21-I22 -> 33529.662 | J23: =IF(I$20<>0,I23/I$20,0) -> 0.58429982
A24: Personnel (sans rémunération de Nathan) | B24: 8026.29 | C24: =IF(B$20<>0,B24/B$20,0) -> 0.16084933 | D24: =$B24 -> 8026.29 | E24: =$B24 -> 8026.29 | F24: =$B24 -> 8026.29 | G24: =$B24 -> 8026.29 | H24: =IF(G$20<>0,G24/G$20,0) -> 0.15318984 | I24: =$B24 -> 8026.29 | J24: =IF(I$20<>0,I24/I$20,0) -> 0.13986898
A25: Loyer + charges locatives + assurance incendie | B25: 4862 | C25: =IF(B$20<>0,B25/B$20,0) -> 0.097435983 | D25: =$B25 -> 4862 | E25: =$B25 -> 4862 | F25: =$B25 -> 4862 | G25: =$B25 -> 4862 | H25: =IF(G$20<>0,G25/G$20,0) -> 0.092796174 | I25: =$B25 -> 4862 | J25: =IF(I$20<>0,I25/I$20,0) -> 0.084726942
A26: Énergie, eau, location panneaux PV | B26: 1297.71 | C26: =IF(B$20<>0,B26/B$20,0) -> 0.026006509 | D26: =$B26 -> 1297.71 | E26: =$B26 -> 1297.71 | F26: =$B26 -> 1297.71 | G26: =$B26 -> 1297.71 | H26: =IF(G$20<>0,G26/G$20,0) -> 0.024768104 | I26: =$B26 -> 1297.71 | J26: =IF(I$20<>0,I26/I$20,0) -> 0.022614356
A27: Autres charges diverses (probablement les redevances) | B27: 1294.29 | C27: =IF(B$20<>0,B27/B$20,0) -> 0.025937972 | D27: =$B27 -> 1294.29 | E27: =$B27 -> 1294.29 | F27: =$B27 -> 1294.29 | G27: =$B27 -> 1294.29 | H27: =IF(G$20<>0,G27/G$20,0) -> 0.02470283 | I27: =$B27 -> 1294.29 | J27: =IF(I$20<>0,I27/I$20,0) -> 0.022554758
A28: Honoraires (fiduciaire, secrétariat social, Indeed…) | B28: 1493 | C28: =IF(B$20<>0,B28/B$20,0) -> 0.029920181 | D28: =$B28 -> 1493 | E28: =$B28 -> 1493 | F28: =$B28 -> 1493 | G28: =$B28 -> 1493 | H28: =IF(G$20<>0,G28/G$20,0) -> 0.028495411 | I28: =$B28 -> 1493 | J28: =IF(I$20<>0,I28/I$20,0) -> 0.026017549
A29: Location containers | B29: 1110 | C29: =IF(B$20<>0,B29/B$20,0) -> 0.022244743 | D29: =$B29 -> 1110 | E29: =$B29 -> 1110 | F29: =$B29 -> 1110 | G29: =$B29 -> 1110 | H29: =IF(G$20<>0,G29/G$20,0) -> 0.02118547 | I29: =$B29 -> 1110 | J29: =IF(I$20<>0,I29/I$20,0) -> 0.019343255
A30: Voiture (location, carburant, assurance) | B30: 946.29 | C30: =IF(B$20<>0,B30/B$20,0) -> 0.018963944 | D30: =$B30 -> 946.29 | E30: =$B30 -> 946.29 | F30: =$B30 -> 946.29 | G30: =$B30 -> 946.29 | H30: =IF(G$20<>0,G30/G$20,0) -> 0.018060899 | I30: =$B30 -> 946.29 | J30: =IF(I$20<>0,I30/I$20,0) -> 0.016490386
A31: Entretien, hygiène, extincteurs | B31: 866.57 | C31: =IF(B$20<>0,B31/B$20,0) -> 0.017366331 | D31: =$B31 -> 866.57 | E31: =$B31 -> 866.57 | F31: =$B31 -> 866.57 | G31: =$B31 -> 866.57 | H31: =IF(G$20<>0,G31/G$20,0) -> 0.016539363 | I31: =$B31 -> 866.57 | J31: =IF(I$20<>0,I31/I$20,0) -> 0.015101157
A32: Admin, IT, téléphone, poste | B32: 666.86 | C32: =IF(B$20<>0,B32/B$20,0) -> 0.013364081 | D32: =$B32 -> 666.86 | E32: =$B32 -> 666.86 | F32: =$B32 -> 666.86 | G32: =$B32 -> 666.86 | H32: =IF(G$20<>0,G32/G$20,0) -> 0.012727696 | I32: =$B32 -> 666.86 | J32: =IF(I$20<>0,I32/I$20,0) -> 0.01162094
A33: Publicité | B33: 632.57 | C33: =IF(B$20<>0,B33/B$20,0) -> 0.012676898 | D33: =$B33 -> 632.57 | E33: =$B33 -> 632.57 | F33: =$B33 -> 632.57 | G33: =$B33 -> 632.57 | H33: =IF(G$20<>0,G33/G$20,0) -> 0.012073236 | I33: =$B33 -> 632.57 | J33: =IF(I$20<>0,I33/I$20,0) -> 0.01102339
A34: Petit matériel, entretien machines | B34: 587.14 | C34: =IF(B$20<>0,B34/B$20,0) -> 0.011766467 | D34: =$B34 -> 587.14 | E34: =$B34 -> 587.14 | F34: =$B34 -> 587.14 | G34: =$B34 -> 587.14 | H34: =IF(G$20<>0,G34/G$20,0) -> 0.011206159 | I34: =$B34 -> 587.14 | J34: =IF(I$20<>0,I34/I$20,0) -> 0.01023171
A35: Caisse, terminal, assurances diverses, intérim, taxes | B35: 438.86 | C35: =IF(B$20<>0,B35/B$20,0) -> 0.00879489 | D35: =$B35 -> 438.86 | E35: =$B35 -> 438.86 | F35: =$B35 -> 438.86 | G35: =$B35 -> 438.86 | H35: =IF(G$20<>0,G35/G$20,0) -> 0.0083760858 | I35: =$B35 -> 438.86 | J35: =IF(I$20<>0,I35/I$20,0) -> 0.0076477305
A36: EBITDA d’exploitation | B36: =B23-SUM(B24:B35) -> 2770.99 | C36: =IF(B$20<>0,B36/B$20,0) -> 0.055531496 | D36: =D23-SUM(D24:D35) -> 5066.6667 | E36: =E23-SUM(E24:E35) -> 10066.667 | F36: =F23-SUM(F24:F35) -> 15066.667 | G36: =G23-SUM(G24:G35) -> 7195.8359 | H36: =IF(G$20<>0,G36/G$20,0) -> 0.13733979 | I36: =I23-SUM(I24:I35) -> 11308.082 | J36: =IF(I$20<>0,I36/I$20,0) -> 0.19705866
A37: Rémunération de Nathan | B37: =-$B$5*$B$7 -> -2166.6667 | C37: =IF(B$20<>0,B37/B$20,0) -> -0.04342067 | D37: =-$B$5*$B$7 -> -2166.6667 | E37: =-$B$5*$B$7 -> -2166.6667 | F37: =-$B$5*$B$7 -> -2166.6667 | G37: =-$B$5*$B$7 -> -2166.6667 | H37: =IF(G$20<>0,G37/G$20,0) -> -0.041353019 | I37: =-$B$5*$B$7 -> -2166.6667 | J37: =IF(I$20<>0,I37/I$20,0) -> -0.037757104
A38: EBITDA, Nathan payé | B38: =B36+B37 -> 604.32333 | C38: =IF(B$20<>0,B38/B$20,0) -> 0.012110826 | D38: =D36+D37 -> 2900 | E38: =E36+E37 -> 7900 | F38: =F36+F37 -> 12900 | G38: =G36+G37 -> 5029.1692 | H38: =IF(G$20<>0,G38/G$20,0) -> 0.095986767 | I38: =I36+I37 -> 9141.4155 | J38: =IF(I$20<>0,I38/I$20,0) -> 0.15930156
A39: Remboursements crédits et leasing | B39: =-$B$6 -> -2900 | C39: =IF(B$20<>0,B39/B$20,0) -> -0.058116896 | D39: =-$B$6 -> -2900 | E39: =-$B$6 -> -2900 | F39: =-$B$6 -> -2900 | G39: =-$B$6 -> -2900 | H39: =IF(G$20<>0,G39/G$20,0) -> -0.055349425 | I39: =-$B$6 -> -2900 | J39: =IF(I$20<>0,I39/I$20,0) -> -0.050536432
A40: Après Nathan et la banque | B40: =B38+B39 -> -2295.6767 | C40: =IF(B$20<>0,B40/B$20,0) -> -0.04600607 | D40: =D38+D39 -> 0 | E40: =E38+E39 -> 5000 | F40: =F38+F39 -> 10000 | G40: =G38+G39 -> 2129.1692 | H40: =IF(G$20<>0,G40/G$20,0) -> 0.040637342 | I40: =I38+I39 -> 6241.4155 | J40: =IF(I$20<>0,I40/I$20,0) -> 0.10876513
A41: CA en plus par mois | D41: =D20-$B$20 -> 4583.4805 | E41: =E20-$B$20 -> 14566.333 | F41: =F20-$B$20 -> 24549.186 | G41: =G20-$B$20 -> 2494.9715 | I41: =I20-$B$20 -> 7484.9145
A42: CA en plus par jour | D42: =D41/$B$8 -> 150.68977 | E42: =E41/$B$8 -> 478.89315 | F42: =F41/$B$8 -> 807.09654 | G42: =G41/$B$8 -> 82.02646 | I42: =I41/$B$8 -> 246.07938
A44: Point mort, Nathan payé (CA par mois) | B44: =IF(B20>0,(SUM(B24:B35)-B37)/(1-(B21+B22)/B20),0) -> 48692.856 | G44: =IF(G20>0,(SUM(G24:G35)-G37)/(1-(G21+G22)/G20),0) -> 43437.112 | I44: =IF(I20>0,(SUM(I24:I35)-I37)/(1-(I21+I22)/I20),0) -> 41739.268
A45: Point mort avec les remboursements (CA par mois) | B45: =IF(B20>0,(SUM(B24:B35)-B37-B39)/(1-(B21+B22)/B20),0) -> 54482.91 | G45: =IF(G20>0,(SUM(G24:G35)-G37-G39)/(1-(G21+G22)/G20),0) -> 48602.208 | I45: =IF(I20>0,(SUM(I24:I35)-I37-I39)/(1-(I21+I22)/I20),0) -> 46702.473
A46: Colonnes D à F : le CA qui donne le résultat visé (ligne 18) ; achats et emballages suivent le CA, les autres charges restent les mêmes. Point mort : charges fixes (Nathan et remboursements compris) ÷ (1 − achats et emballages en % du CA).
...

Sheet Application ou bilan
A1: L’application ou le bilan : mars → septembre 2026, en € par mois
A2: Application : la caisse et le P&L du panel (feuille « Mois par mois », main-d’œuvre encodée, food cost mesuré par le panel). Bilan : la situation au 30/09 de la fiduciaire, ramenée au mois (feuille « Compte d’exploitation », colonne Analyse, à valider). En vert : liens ; en noir : calculs.
A4: Poste | B4: Application | C4: % CA | D4: Bilan | E4: % CA | F4: Écart (bilan − application) | G4: Ce qui change d’une source à l’autre
A5: Chiffre d’affaires | B5: =AVERAGE('Mois par mois'!C5:C11) -> 51603.366 | D5: ='Compte d’exploitation'!B20 -> 49899.43 | F5: =D5-B5 -> -1703.9357 | G5: caisse HT, contre CA comptable
A6: Matière | B6: =SUMPRODUCT('Mois par mois'!C5:C11,'Mois par mois'!T5:T11)/7 -> 19309.876 | C6: =IF(B$5>0,B6/B$5,0) -> 0.374198 | D6: ='Compte d’exploitation'!B21+'Compte d’exploitation'!B22 -> 24906.86 | E6: =IF(D$5>0,D6/D$5,0) -> 0.49914117 | F6: =D6-B6 -> 5596.9838 | G6: application : coût de recette des ventes (panel) ; bilan : achats + emballages
A7: Marge brute | B7: =B5-B6 -> 32293.49 | C7: =IF(B$5>0,B7/B$5,0) -> 0.625802 | D7: =D5-D6 -> 24992.57 | E7: =IF(D$5>0,D7/D$5,0) -> 0.50085883 | F7: =D7-B7 -> -7300.9195
A8: Personnel | B8: =AVERAGE('Mois par mois'!U5:U11) -> 8099.8571 | C8: =IF(B$5>0,B8/B$5,0) -> 0.15696374 | D8: ='Compte d’exploitation'!B24 -> 8026.29 | E8: =IF(D$5>0,D8/D$5,0) -> 0.16084933 | F8: =D8-B8 -> -73.567143 | G8: heures planifiées × taux du panel, contre salaires ; Nathan absent des deux
A9: Frais généraux | B9: =AVERAGE('Mois par mois'!P5:P11) -> 12612.671 | C9: =IF(B$5>0,B9/B$5,0) -> 0.24441567 | D9: =SUM('Compte d’exploitation'!B25:B35) -> 14195.29 | E9: =IF(D$5>0,D9/D$5,0) -> 0.284478 | F9: =D9-B9 -> 1582.6186 | G9: montant saisi au panel, contre factures
A10: Résultat · EBITDA | B10: =B7-B8-B9 -> 11580.961 | C10: =IF(B$5>0,B10/B$5,0) -> 0.22442259 | D10: =D7-D8-D9 -> 2770.99 | E10: =IF(D$5>0,D10/D$5,0) -> 0.055531496 | F10: =D10-B10 -> -8809.971 | G10: avant Nathan, amortissements, charges financières
A11: Point mort (CA par mois) | B11: =IF(B5>0,(B8+B9)/(1-B6/B5),0) -> 33097.575 | D11: =IF(D5>0,(D8+D9)/(1-D6/D5),0) -> 44366.953 | F11: =D11-B11 -> 11269.378 | G11: charges fixes ÷ (1 − matière en % du CA), Nathan non payé
A12: Clients par mois (application) | B12: =AVERAGE('Mois par mois'!F5:F11) -> 4235.5714
A13: Panier moyen (application) | B13: =IF(B12>0,B5/B12,0) -> 12.18333
A15: Du résultat de l’application à l’EBITDA du bilan
A16: Résultat de l’application | B16: =B10 -> 11580.961
A17: Écart de CA | B17: =D5-B5 -> -1703.9357
A18: Écart de matière | B18: =-(D6-B6) -> -5596.9838
A19: Écart de personnel | B19: =-(D8-B8) -> 73.567143
A20: Écart de frais généraux | B20: =-(D9-B9) -> -1582.6186
A21: EBITDA du bilan (somme des lignes) | B21: =SUM(B16:B20) -> 2770.99 | C21: =IF(ABS(B21-D10)<1,"= bilan","écart") -> = bilan

Sheet Euros par jour
A1: Ce que rapportent quelques euros de plus par jour
A2: À personnel et frais généraux égaux, un euro vendu en plus ne coûte que sa matière. Paliers en bleu (modifiables) ; liens en vert vers « Récap » et « Compte d’exploitation ».
A4: Jours par mois | B4: =Récap!B13 -> 30.416667 | D4: Taux de marge, bilan | F4: =1-('Compte d’exploitation'!B21+'Compte d’exploitation'!B22)/'Compte d’exploitation'!B20 -> 0.50085883
A5: Panier moyen | B5: =Récap!B9 -> 12.18333 | D5: EBITDA Nathan payé, bilan | F5: ='Compte d’exploitation'!B38 -> 604.32333
A6: Clients par jour | B6: =Récap!B8 -> 139.19718 | D6: Après remboursements, bilan | F6: ='Compte d’exploitation'!B40 -> -2295.6767
A7: Taux de marge, récap | B7: =1-Récap!B31 -> 0.55
A8: Résultat actuel, récap | B8: =Récap!B25 -> 4195.7103
A10: € par jour en plus | B10: CA en plus par mois | C10: CA en plus par an | D10: Clients par jour en plus | E10: ou panier en plus | F10: Marge directe par mois (récap) | G10: Résultat par mois (récap) | H10: Marge directe par mois (bilan) | I10: EBITDA Nathan payé (bilan) | J10: Après remboursements (bilan)
A11: 0 | B11: =A11*$B$4 -> 0 | C11: =A11*365 -> 0 | D11: =IF($B$5>0,A11/$B$5,0) -> 0 | E11: =IF($B$6>0,A11/$B$6,0) -> 0 | F11: =B11*$B$7 -> 0 | G11: =$B$8+F11 -> 4195.7103 | H11: =B11*$F$4 -> 0 | I11: =$F$5+H11 -> 604.32333 | J11: =$F$6+H11 -> -2295.6767
A12: 50 | B12: =A12*$B$4 -> 1520.8333 | C12: =A12*365 -> 18250 | D12: =IF($B$5>0,A12/$B$5,0) -> 4.1039682 | E12: =IF($B$6>0,A12/$B$6,0) -> 0.35920267 | F12: =B12*$B$7 -> 836.45833 | G12: =$B$8+F12 -> 5032.1687 | H12: =B12*$F$4 -> 761.7228 | I12: =$F$5+H12 -> 1366.0461 | J12: =$F$6+H12 -> -1533.9539
A13: 100 | B13: =A13*$B$4 -> 3041.6667 | C13: =A13*365 -> 36500 | D13: =IF($B$5>0,A13/$B$5,0) -> 8.2079364 | E13: =IF($B$6>0,A13/$B$6,0) -> 0.71840534 | F13: =B13*$B$7 -> 1672.9167 | G13: =$B$8+F13 -> 5868.627 | H13: =B13*$F$4 -> 1523.4456 | I13: =$F$5+H13 -> 2127.7689 | J13: =$F$6+H13 -> -772.23107
A14: 150 | B14: =A14*$B$4 -> 4562.5 | C14: =A14*365 -> 54750 | D14: =IF($B$5>0,A14/$B$5,0) -> 12.311905 | E14: =IF($B$6>0,A14/$B$6,0) -> 1.077608 | F14: =B14*$B$7 -> 2509.375 | G14: =$B$8+F14 -> 6705.0853 | H14: =B14*$F$4 -> 2285.1684 | I14: =$F$5+H14 -> 2889.4917 | J14: =$F$6+H14 -> -10.508266
A15: 200 | B15: =A15*$B$4 -> 6083.3333 | C15: =A15*365 -> 73000 | D15: =IF($B$5>0,A15/$B$5,0) -> 16.415873 | E15: =IF($B$6>0,A15/$B$6,0) -> 1.4368107 | F15: =B15*$B$7 -> 3345.8333 | G15: =$B$8+F15 -> 7541.5437 | H15: =B15*$F$4 -> 3046.8912 | I15: =$F$5+H15 -> 3651.2145 | J15: =$F$6+H15 -> 751.21453
A16: 250 | B16: =A16*$B$4 -> 7604.1667 | C16: =A16*365 -> 91250 | D16: =IF($B$5>0,A16/$B$5,0) -> 20.519841 | E16: =IF($B$6>0,A16/$B$6,0) -> 1.7960134 | F16: =B16*$B$7 -> 4182.2917 | G16: =$B$8+F16 -> 8378.002 | H16: =B16*$F$4 -> 3808.614 | I16: =$F$5+H16 -> 4412.9373 | J16: =$F$6+H16 -> 1512.9373
A18: Ligne 0 : aujourd’hui, moyenne de mars à septembre (le bilan de la page 3). Une vente faite avec une remise rapporte moins que la marge directe.
